2025-01-12 02:40:42,013 - ERROR - 获取customer-all 发生异常!
Traceback (most recent call last):
  File "urllib3\connection.py", line 203, in _new_conn
  File "urllib3\util\connection.py", line 85, in create_connection
  File "urllib3\util\connection.py", line 73, in create_connection
ConnectionRefusedError: [WinError 10061] 由于目标计算机积极拒绝，无法连接。

The above exception was the direct cause of the following exception:

Traceback (most recent call last):
  File "urllib3\connectionpool.py", line 790, in urlopen
  File "urllib3\connectionpool.py", line 496, in _make_request
  File "urllib3\connection.py", line 395, in request
  File "http\client.py", line 1277, in endheaders
  File "http\client.py", line 1037, in _send_output
  File "http\client.py", line 975, in send
  File "urllib3\connection.py", line 243, in connect
  File "urllib3\connection.py", line 218, in _new_conn
urllib3.exceptions.NewConnectionError: <urllib3.connection.HTTPConnection object at 0x000001AB6179EDD0>: Failed to establish a new connection: [WinError 10061] 由于目标计算机积极拒绝，无法连接。

The above exception was the direct cause of the following exception:

Traceback (most recent call last):
  File "requests\adapters.py", line 486, in send
  File "urllib3\connectionpool.py", line 844, in urlopen
  File "urllib3\util\retry.py", line 515, in increment
urllib3.exceptions.MaxRetryError: HTTPConnectionPool(host='127.0.0.1', port=13301): Max retries exceeded with url: /daily%2Fwork%2Fhis_consumer (Caused by NewConnectionError('<urllib3.connection.HTTPConnection object at 0x000001AB6179EDD0>: Failed to establish a new connection: [WinError 10061] 由于目标计算机积极拒绝，无法连接。'))

During handling of the above exception, another exception occurred:

Traceback (most recent call last):
  File "yixin-v2.0.0.py", line 317, in <module>
  File "requests\api.py", line 73, in get
  File "requests\api.py", line 59, in request
  File "requests\sessions.py", line 589, in request
  File "requests\sessions.py", line 703, in send
  File "requests\adapters.py", line 519, in send
requests.exceptions.ConnectionError: HTTPConnectionPool(host='127.0.0.1', port=13301): Max retries exceeded with url: /daily%2Fwork%2Fhis_consumer (Caused by NewConnectionError('<urllib3.connection.HTTPConnection object at 0x000001AB6179EDD0>: Failed to establish a new connection: [WinError 10061] 由于目标计算机积极拒绝，无法连接。'))
2025-01-12 02:40:59,968 - ERROR - 获取customer-all 发生异常!
Traceback (most recent call last):
  File "urllib3\connection.py", line 203, in _new_conn
  File "urllib3\util\connection.py", line 85, in create_connection
  File "urllib3\util\connection.py", line 73, in create_connection
ConnectionRefusedError: [WinError 10061] 由于目标计算机积极拒绝，无法连接。

The above exception was the direct cause of the following exception:

Traceback (most recent call last):
  File "urllib3\connectionpool.py", line 790, in urlopen
  File "urllib3\connectionpool.py", line 496, in _make_request
  File "urllib3\connection.py", line 395, in request
  File "http\client.py", line 1277, in endheaders
  File "http\client.py", line 1037, in _send_output
  File "http\client.py", line 975, in send
  File "urllib3\connection.py", line 243, in connect
  File "urllib3\connection.py", line 218, in _new_conn
urllib3.exceptions.NewConnectionError: <urllib3.connection.HTTPConnection object at 0x00000247E455EF10>: Failed to establish a new connection: [WinError 10061] 由于目标计算机积极拒绝，无法连接。

The above exception was the direct cause of the following exception:

Traceback (most recent call last):
  File "requests\adapters.py", line 486, in send
  File "urllib3\connectionpool.py", line 844, in urlopen
  File "urllib3\util\retry.py", line 515, in increment
urllib3.exceptions.MaxRetryError: HTTPConnectionPool(host='127.0.0.1', port=13301): Max retries exceeded with url: /daily%2Fwork%2Fhis_consumer (Caused by NewConnectionError('<urllib3.connection.HTTPConnection object at 0x00000247E455EF10>: Failed to establish a new connection: [WinError 10061] 由于目标计算机积极拒绝，无法连接。'))

During handling of the above exception, another exception occurred:

Traceback (most recent call last):
  File "yixin-v2.0.0.py", line 317, in <module>
  File "requests\api.py", line 73, in get
  File "requests\api.py", line 59, in request
  File "requests\sessions.py", line 589, in request
  File "requests\sessions.py", line 703, in send
  File "requests\adapters.py", line 519, in send
requests.exceptions.ConnectionError: HTTPConnectionPool(host='127.0.0.1', port=13301): Max retries exceeded with url: /daily%2Fwork%2Fhis_consumer (Caused by NewConnectionError('<urllib3.connection.HTTPConnection object at 0x00000247E455EF10>: Failed to establish a new connection: [WinError 10061] 由于目标计算机积极拒绝，无法连接。'))
